Workbook
Name Argus_Import: #REF!
Name Artist: #REF!
Name Backoffice.comp: #REF!
Name Cash_Flow: #REF!
Name Ccy: Inputs!$C$9
Name Choices_Wrapper: [0]!Choices_Wrapper
Name circ: Inputs!#REF!
Name Computer: #REF!
Name CoName: Inputs!$C$6
Name Currency: #REF!
Name Currency_Options: #REF!
Name days: #REF!
Name Design.comp: #REF!
Name Engineer.comp: #REF!
Name ev.Calculation: -4105
Name ev.Initialized: FALSE
Name Excel_Version: #REF!
Name Expiration: #REF!
Name FYE: #REF!
Name hn.ExtDb: FALSE
Name hn.ModelType: "DEAL"
Name hn.ModelVersion: 1
Name hn.NoUpload: 0
Name In_place_NOI: #REF!
Name IQ_ADDIN: "AUTO"
Name IQ_CH: 110000
Name IQ_CQ: 5000
Name IQ_CY: 10000
Name IQ_DAILY: 500000
Name IQ_FH: 100000
Name IQ_FQ: 500
Name IQ_FY: 1000
Name IQ_LTM: 2000
Name IQ_MONTH: 15000
Name IQ_NTM: 6000
Name IQ_WEEK: 50000
Name IQ_YTD: 3000
Name IsColHidden: FALSE
Name IsLTMColHidden: FALSE
Name LTV: #REF!
Name Marketing.comp: #REF!
Name Maturity: #REF!
Name Name: #REF!
Name OS: #REF!
Name Par: #REF!
Name ProjectName: {"Client Name or Project Name"}
Name Purchase.price: #REF!
Name Recap: #REF!
Name Sales.commission.percentage: #REF!
Name Sales.comp: #REF!
Name scale: #REF!
Name Scenario: #REF!
Name Series_One: OFFSET(#REF!,0,0,24,1)
Name Sq.footage: #REF!
Name SquareFeet: #REF!
Name Start_Date: #REF!
Name Subheader: #REF!
Name TTS: #REF!
Name Units: Inputs!$C$10
Name Version: #REF!

Sheet Inputs
A1: ServiceNow
A2: Financial modeling fundamentals
A4: Model information
B6: Company name | C6: ServiceNow
B7: Company Ticker | C7: $NOW
B8: Fiscal year ending | C8: 31-Dec
B9: Currency | C9: USD
B10: Units | C10: m
B11: Analyst name | C11: Aryaan Rajwani

Sheet Assumptions
B1: IMPACT INVESTMENT FUND
B2: ServiceNow
B3: Financial Model
B4: Supporting Schedules
B6: Years | D6: 2020A | E6: 2021A | F6: 2022A | G6: 2023A | H6: 2024A | I6: 2025A | J6: 2026E | K6: 2027E | L6: 2028E | M6: 2029E | N6: 2030E | O6: 2031E | P6: 2032E | Q6: 2033E | R6: 2034E
B9: Revenue
B11: Revenue | D11: =IS!D4 -> 4519.5 | E11: =IS!E4 -> 5896 | F11: =IS!F4 -> 7245 | G11: =IS!G4 -> 8971 | H11: =IS!H4 -> 10984 | I11: =IS!I4 -> 13278 | J11: 15530 | K11: =J14+J17 -> 19295.342 | L11: =K14+K17 -> 23635.238 | M11: =L14+L17 -> 27561.156 | N11: =M14+M17 -> 31577.855 | O11: =N14+N17 -> 34633.439 | P11: =O14+O17 -> 37773.929 | Q11: =P14+P17 -> 40655.401 | R11: =Q14+Q17 -> 43743.444
B12: Revenue Growth % | E12: =(E11-D11)/D11 -> 0.30456909 | F12: =(F11-E11)/E11 -> 0.22879919 | G12: =(G11-F11)/F11 -> 0.23823326 | H12: =(H11-G11)/G11 -> 0.2243897 | I12: =(I11-H11)/H11 -> 0.20884924 | J12: =(J11-I11)/I11 -> 0.16960386 | K12: =(K11-J11)/J11 -> 0.24245605 | L12: =(L11-K11)/K11 -> 0.22491935 | ... R12: =(R11-Q11)/Q11 -> 0.075956522
B14: crpo | D14: 4400 | E14: 5800 | F14: 7120 | G14: 8520 | H14: 10490 | I14: 12850 | J14: =J20*J23 -> 15560.76 | K14: =K20*K23 -> 18984.127 | L14: =L20*L23 -> 22591.111 | M14: =M20*M23 -> 26205.689 | N14: =N20*N23 -> 29350.372 | O14: =O20*O23 -> 32285.409 | P14: =P20*P23 -> 35352.523 | Q14: =Q20*Q23 -> 38711.013 | R14: =R20*R23 -> 41033.673
B15: crpo growth | E15: =(E14-D14)/D14 -> 0.31818182 | F15: =(F14-E14)/E14 -> 0.22758621 | G15: =(G14-F14)/F14 -> 0.19662921 | H15: =(H14-G14)/G14 -> 0.23122066 | I15: =(I14-H14)/H14 -> 0.22497617 | J15: =(J14-I14)/I14 -> 0.21095409 | K15: =(K14-J14)/J14 -> 0.22 | L15: =(L14-K14)/K14 -> 0.19 | ... R15: =(R14-Q14)/Q14 -> 0.06
B17: NNACV ($) | E17: =E11-D14 -> 1496 | F17: =F11-E14 -> 1445 | G17: =G11-F14 -> 1851 | H17: =H11-G14 -> 2464 | I17: =I11-H14 -> 2788 | J17: =J14*J18 -> 3734.5824 | K17: =K14*K18 -> 4651.1112 | L17: =L14*L18 -> 4970.0445 | M17: =M14*M18 -> 5372.1663 | N17: =N14*N18 -> 5283.0669 | O17: =O14*O18 -> 5488.5195 | P17: =P14*P18 -> 5302.8784 | Q17: =Q14*Q18 -> 5032.4316 | R17: =R14*R18 -> 4513.7041
B18: % of crpo | E18: =E17/E14 -> 0.25793103 | F18: =F17/F14 -> 0.20294944 | G18: =G17/G14 -> 0.21725352 | H18: =H17/H14 -> 0.23489037 | I18: =J18 -> 0.24 | J18: 0.24 | K18: 0.245 | L18: 0.22 | M18: 0.205 | N18: 0.18 | O18: 0.17 | P18: 0.15 | Q18: 0.13 | R18: 0.11
B20: rpo | D20: 8900 | E20: 11500 | F20: 14400 | G20: 18000 | H20: 22300 | I20: 28200 | J20: =I20+I20*J21 -> 34968 | K20: =J20+J20*K21 -> 42660.96 | L20: =K20+K20*L21 -> 50766.542 | M20: =L20+L20*M21 -> 58889.189 | N20: =M20+M20*N21 -> 65955.892 | O20: =N20+N20*O21 -> 72551.481 | P20: =O20*(1+P21) -> 79443.872 | Q20: =P20*(1+Q21) -> 86991.04 | R20: =Q20*(1+R21) -> 92210.502
B21: rpo growth | E21: =(E20-D20)/D20 -> 0.29213483 | F21: =(F20-E20)/E20 -> 0.25217391 | G21: =(G20-F20)/F20 -> 0.25 | H21: =(H20-G20)/G20 -> 0.23888889 | I21: =(I20-H20)/H20 -> 0.26457399 | J21: 0.24 | K21: 0.22 | L21: 0.19 | M21: 0.16 | N21: 0.12 | O21: 0.1 | P21: 0.095 | Q21: 0.095 | R21: 0.06
B23: crpo/rpo ratio | D23: =D14/D20 -> 0.49438202 | E23: =E14/E20 -> 0.50434783 | F23: =F14/F20 -> 0.49444444 | G23: =G14/G20 -> 0.47333333 | H23: =H14/H20 -> 0.47040359 | I23: =I14/I20 -> 0.45567376 | J23: 0.445 | K23: 0.445 | L23: 0.445 | M23: 0.445 | N23: 0.445 | O23: 0.445 | P23: 0.445 | Q23: 0.445 | R23: 0.445
B25: def rev | D25: 2962 | E25: 3836 | F25: 4660 | G25: 5785 | H25: 6819 | I25: 8314 | J25: =J26*J14 -> 10067.872 | K25: =K26*K14 -> 12719.365 | L25: =L26*L14 -> 15813.778 | M25: =M26*M14 -> 18343.982 | N25: =N26*N14 -> 21132.268 | O25: =O26*O14 -> 23891.203 | P25: =P26*P14 -> 26514.392 | Q25: =Q26*Q14 -> 29033.259 | R25: =R26*R14 -> 30775.255
B26: % of crpo of current year | D26: =D25/D14 -> 0.67318182 | E26: =E25/E14 -> 0.66137931 | F26: =F25/F14 -> 0.65449438 | G26: =G25/G14 -> 0.67899061 | H26: =H25/H14 -> 0.65004766 | I26: =I25/I14 -> 0.64700389 | J26: =I26 -> 0.64700389 | K26: 0.67 | L26: 0.7 | M26: 0.7 | N26: 0.72 | O26: 0.74 | P26: 0.75 | Q26: 0.75 | R26: 0.75
B28: No . Of customers with acv > 1M | G28: 1897 | H28: 2109 | I28: 2344
B29: growth | H29: =(H28-G28)/G28 -> 0.1117554 | I29: =(I28-H28)/H28 -> 0.11142722
B32: No . Of customers with acv > 5M | G32: 420 | H32: 502 | I32: 603
B33: growth | H33: =(H32-G32)/G32 -> 0.1952381 | I33: =(I32-H32)/H32 -> 0.20119522
B35: Costs
B37: Cost of Revenue | D37: =IS!D5 -> 987.1 | E37: =IS!E5 -> 1353 | F37: =IS!F5 -> 1573 | G37: =IS!G5 -> 1921 | H37: =IS!H5 -> 2287 | I37: =IS!I5 -> 2983 | J37: =J11*J38 -> 3571.9 | K37: =K11*K38 -> 4534.4055 | L37: =L11*L38 -> 5433.4051 | M37: =M11*M38 -> 6383.9517 | N37: =N11*N38 -> 7331.4767 | O37: =O11*O38 -> 8008.2419 | P37: =P11*P38 -> 8751.3209 | Q37: =Q11*Q38 -> 9419.5351 | R37: =R11*R38 -> 10128.021 | AE37: hosting services and customer support; (data centre capacity cost, public cloud cost, data connectivity service cost and related expenses
B38: % of Revenue | D38: =D37/D11 -> 0.21840912 | E38: =E37/E11 -> 0.22947761 | F38: =F37/F11 -> 0.21711525 | G38: =G37/G11 -> 0.21413443 | H38: =H37/H11 -> 0.20821194 | I38: =I37/I11 -> 0.22465733 | J38: 0.23 | K38: 0.235 | L38: =AVERAGE(I38:K38) -> 0.22988578 | M38: =AVERAGE(J38:L38) -> 0.23162859 | N38: =AVERAGE(K38:M38) -> 0.23217146 | O38: =AVERAGE(L38:N38) -> 0.23122861 | P38: =AVERAGE(M38:O38) -> 0.23167622 | Q38: =AVERAGE(N38:P38) -> 0.23169209 | R38: =AVERAGE(O38:Q38) -> 0.23153231 | AE38: 0.5% increase followed by trailing 3Y AVG
B39: COGS Margin % | D39: =1- (D37/D11) -> 0.78159088 | E39: =1- (E37/E11) -> 0.77052239 | F39: =1- (F37/F11) -> 0.78288475 | G39: =1- (G37/G11) -> 0.78586557 | H39: =1- (H37/H11) -> 0.79178806 | I39: =1- (I37/I11) -> 0.77534267 | J39: =1- (J37/J11) -> 0.77 | K39: =1- (K37/K11) -> 0.765 | ... R39: =1- (R37/R11) -> 0.76846769 | AE39: expected to decrease as public cloud offerings expand and customer support in more regulated areas increase
B41: Operating Expenses
B42: Selling & Marketing | D42: =IS!D7 -> 1855 | E42: =IS!E7 -> 2292 | F42: =IS!F7 -> 2814 | G42: =IS!G7 -> 3301 | H42: =IS!H7 -> 3854 | I42: =IS!I7 -> 4388 | J42: =J11*J43 -> 4969.6 | K42: =K11*K43 -> 5981.5561 | L42: =L11*L43 -> 7326.9239 | M42: =M11*M43 -> 8543.9583 | N42: =N11*N43 -> 8526.021 | O42: =O11*O43 -> 8658.3597 | P42: =P11*P43 -> 9065.7429 | Q42: =Q11*Q43 -> 9757.2963 | R42: =R11*R43 -> 9623.5577 | AE42: management expects increase in absolute amount to increase while % to rev slightly declining with sales productivity and marketing efficiencies
B43: % of Revenue | D43: =D42/D11 -> 0.41044363 | E43: =E42/E11 -> 0.38873813 | F43: =F42/F11 -> 0.3884058 | G43: =G42/G11 -> 0.36796344 | H43: =H42/H11 -> 0.350874 | I43: =I42/I11 -> 0.33047146 | J43: 0.32 | K43: 0.31 | L43: 0.31 | M43: 0.31 | N43: 0.27 | O43: 0.25 | P43: 0.24 | Q43: 0.24 | R43: 0.22 | AE43: blend of Ai effeciencies and new customer push. At maturity, this % drops as no new customers needed plus AI efficiency
B44: General & Administrative | D44: =IS!D8 -> 454 | E44: =IS!E8 -> 597 | F44: =IS!F8 -> 735 | G44: =IS!G8 -> 863 | H44: =IS!H8 -> 936 | I44: =IS!I8 -> 1123 | J44: =J11*J45 -> 1242.4 | K44: =K11*K45 -> 1447.1507 | L44: =L11*L45 -> 1418.1143 | M44: =M11*M45 -> 1378.0578 | N44: =N11*N45 -> 1263.1142 | O44: =O11*O45 -> 1039.0032 | P44: =P11*P45 -> 755.47857 | Q44: =Q11*Q45 -> 813.10803 | R44: =R11*R45 -> 874.86889 | AE44: management expects absolute amount to decrease in guidance YE 2026. Assuming flat expense amounts
B45: % of Revenue | D45: =D44/D11 -> 0.10045359 | E45: =E44/E11 -> 0.10125509 | F45: =F44/F11 -> 0.10144928 | G45: =G44/G11 -> 0.096198863 | H45: =H44/H11 -> 0.085214858 | I45: =I44/I11 -> 0.08457599 | J45: 0.08 | K45: 0.075 | L45: 0.06 | M45: 0.05 | N45: 0.04 | O45: 0.03 | P45: 0.02 | Q45: 0.02 | R45: 0.02 | AE45: internal AI efficiency to decrease G&A blended with a mix of employee headcount increase and termination costs
B46: Research & Development | D46: =IS!D9 -> 1024.3 | E46: =IS!E9 -> 1397 | F46: =IS!F9 -> 1768 | G46: =IS!G9 -> 2124 | H46: =IS!H9 -> 2543 | I46: =IS!I9 -> 2960 | J46: =J11*J47 -> 3463.19 | K46: =K11*K47 -> 4244.9753 | L46: =L11*L47 -> 5081.5762 | M46: =M11*M47 -> 5787.8427 | N46: =N11*N47 -> 6473.4604 | O46: =O11*O47 -> 6926.6878 | P46: =P11*P47 -> 7554.7857 | Q46: =Q11*Q47 -> 8131.0803 | R46: =R11*R47 -> 8311.2544
B47: % of Revenue | D47: =D46/D11 -> 0.22664012 | E47: =E46/E11 -> 0.2369403 | F47: =F46/F11 -> 0.24403037 | G47: =G46/G11 -> 0.2367629 | H47: =H46/H11 -> 0.23151857 | I47: =I46/I11 -> 0.22292514 | J47: 0.223 | K47: 0.22 | L47: 0.215 | M47: 0.21 | N47: 0.205 | O47: 0.2 | P47: 0.2 | Q47: 0.2 | R47: 0.19 | AE47: flat w rev. declining at maturity
B48: Total Operating Expenses | D48: =D42+D44+D46 -> 3333.3 | E48: =E42+E44+E46 -> 4286 | F48: =F42+F44+F46 -> 5317 | G48: =G42+G44+G46 -> 6288 | H48: =H42+H44+H46 -> 7333 | I48: =I42+I44+I46 -> 8471 | J48: =J42+J44+J46 -> 9675.19 | K48: =K42+K44+K46 -> 11673.682 | ... R48: =R42+R44+R46 -> 18809.681
B49: % of Revenue | D49: =D48/D11 -> 0.73753734 | E49: =E48/E11 -> 0.72693351 | F49: =F48/F11 -> 0.73388544 | G49: =G48/G11 -> 0.7009252 | H49: =H48/H11 -> 0.66760743 | I49: =I48/I11 -> 0.63797259 | J49: =J48/J11 -> 0.623 | K49: =K48/K11 -> 0.605 | ... R49: =R48/R11 -> 0.43
B51: Non Operating Income/Expense
B52: Interest Income | E52: =ABS(IS!E18) -> 20 | F52: =ABS(IS!F18) -> 82 | G52: =ABS(IS!G18) -> 302 | H52: =ABS(IS!H18) -> 419 | I52: =ABS(IS!I18) -> 451 | J52: =J11*J53 -> 310.6 | K52: =K11*K53 -> 385.90685 | L52: =L11*L53 -> 472.70477 | M52: =M11*M53 -> 551.22312 | N52: =N11*N53 -> 631.55711 | O52: =O11*O53 -> 692.66878 | P52: =P11*P53 -> 755.47857 | Q52: =Q11*Q53 -> 813.10803 | R52: =R11*R53 -> 874.86889
B53: % of Revenue | E53: =E52/E11 -> 0.0033921303 | F53: =F52/F11 -> 0.01131815 | G53: =G52/G11 -> 0.033664029 | H53: =H52/H11 -> 0.038146395 | I53: =I52/I11 -> 0.033965959 | J53: 0.02 | K53: 0.02 | L53: 0.02 | M53: 0.02 | N53: 0.02 | O53: 0.02 | P53: 0.02 | Q53: 0.02 | R53: 0.02
B56: Cash Reconciliation
B58: Beginning Cash Balance | J58: =I62 -> 3726 | K58: =J62 -> 5447.045 | L58: =K62 -> 7409.3886 | M58: =L62 -> 10199.963 | N58: =M62 -> 13607.563 | O58: =N62 -> 19223.1 | P58: =O62 -> 27705.276 | Q58: =P62 -> 36814.717 | R58: =Q62 -> 47072.425
B59: Plus: Cash Flow from Operating Activities | J59: =CFS!I11 -> 6058.0443 | K59: =CFS!J11 -> 7363.2257 | L59: =CFS!K11 -> 9233.0313 | M59: =CFS!L11 -> 10103.248 | N59: =CFS!M11 -> 11832.718 | O59: =CFS!N11 -> 14793.526 | P59: =CFS!O11 -> 14827.825 | Q59: =CFS!P11 -> 15296.526 | R59: =CFS!Q11 -> 17614.394
...

Sheet IS
A1: =CoName -> ServiceNow
D2: Hist. | E2: Hist. | F2: Hist. | G2: Hist. | H2: Hist. | I2: Hist. | J2: Proj. | K2: Proj. | L2: Proj. | M2: Proj. | N2: Proj. | O2: Proj. | P2: Proj. | Q2: Proj. | R2: Proj.
A3: Income statement | D3: 2020 | E3: 2021 | F3: =E3+1 -> 2022 | G3: =F3+1 -> 2023 | H3: =G3+1 -> 2024 | I3: =H3+1 -> 2025 | J3: =I3+1 -> 2026 | K3: =J3+1 -> 2027 | L3: =K3+1 -> 2028 | M3: =L3+1 -> 2029 | ... R3: =Q3+1 -> 2034
B4: Revenue | D4: 4519.5 | E4: 5896 | F4: 7245 | G4: 8971 | H4: 10984 | I4: 13278 | J4: =Assumptions!J11 -> 15530 | K4: =Assumptions!K11 -> 19295.342 | L4: =Assumptions!L11 -> 23635.238 | M4: =Assumptions!M11 -> 27561.156 | N4: =Assumptions!N11 -> 31577.855 | O4: =Assumptions!O11 -> 34633.439 | P4: =Assumptions!P11 -> 37773.929 | Q4: =Assumptions!Q11 -> 40655.401 | R4: =Assumptions!R11 -> 43743.444
B5: Cost of goods sold | D5: 987.1 | E5: 1353 | F5: 1573 | G5: 1921 | H5: 2287 | I5: 2983 | J5: =Assumptions!J37 -> 3571.9 | K5: =Assumptions!K37 -> 4534.4055 | L5: =Assumptions!L37 -> 5433.4051 | M5: =Assumptions!M37 -> 6383.9517 | N5: =Assumptions!N37 -> 7331.4767 | O5: =Assumptions!O37 -> 8008.2419 | P5: =Assumptions!P37 -> 8751.3209 | Q5: =Assumptions!Q37 -> 9419.5351 | R5: =Assumptions!R37 -> 10128.021
B6: Gross Profit | D6: =D4-D5 -> 3532.4 | E6: =E4-E5 -> 4543 | F6: =F4-F5 -> 5672 | G6: =G4-G5 -> 7050 | H6: =H4-H5 -> 8697 | I6: =I4-I5 -> 10295 | J6: =J4-J5 -> 11958.1 | K6: =K4-K5 -> 14760.937 | ... R6: =R4-R5 -> 33615.424
B7: Selling & Marketing | D7: 1855 | E7: 2292 | F7: 2814 | G7: 3301 | H7: 3854 | I7: 4388 | J7: =Assumptions!J42 -> 4969.6 | K7: =Assumptions!K42 -> 5981.5561 | L7: =Assumptions!L42 -> 7326.9239 | M7: =Assumptions!M42 -> 8543.9583 | N7: =Assumptions!N42 -> 8526.021 | O7: =Assumptions!O42 -> 8658.3597 | P7: =Assumptions!P42 -> 9065.7429 | Q7: =Assumptions!Q42 -> 9757.2963 | R7: =Assumptions!R42 -> 9623.5577
B8: General & Admin | D8: 454 | E8: 597 | F8: 735 | G8: 863 | H8: 936 | I8: 1123 | J8: =Assumptions!J44 -> 1242.4 | K8: =Assumptions!K44 -> 1447.1507 | L8: =Assumptions!L44 -> 1418.1143 | M8: =Assumptions!M44 -> 1378.0578 | N8: =Assumptions!N44 -> 1263.1142 | O8: =Assumptions!O44 -> 1039.0032 | P8: =Assumptions!P44 -> 755.47857 | Q8: =Assumptions!Q44 -> 813.10803 | R8: =Assumptions!R44 -> 874.86889
B9: R&D | D9: 1024.3 | E9: 1397 | F9: 1768 | G9: 2124 | H9: 2543 | I9: 2960 | J9: =Assumptions!J46 -> 3463.19 | K9: =Assumptions!K46 -> 4244.9753 | L9: =Assumptions!L46 -> 5081.5762 | M9: =Assumptions!M46 -> 5787.8427 | N9: =Assumptions!N46 -> 6473.4604 | O9: =Assumptions!O46 -> 6926.6878 | P9: =Assumptions!P46 -> 7554.7857 | Q9: =Assumptions!Q46 -> 8131.0803 | R9: =Assumptions!R46 -> 8311.2544
B10: Other expense | D10: 0 | E10: 0 | F10: 0 | G10: 0 | H10: 0 | I10: 0 | J10: 0 | K10: 0 | L10: 0 | M10: 0 | N10: 0 | O10: 0 | P10: 0
B11: Total Op Exp | D11: =D8+D9+D10+D7 -> 3333.3 | E11: =E8+E9+E10+E7 -> 4286 | F11: =F8+F9+F10+F7 -> 5317 | G11: =G8+G9+G10+G7 -> 6288 | H11: =H8+H9+H10+H7 -> 7333 | I11: =I8+I9+I10+I7 -> 8471 | J11: =J8+J9+J10+J7 -> 9675.19 | K11: =K8+K9+K10+K7 -> 11673.682 | ... R11: =R8+R9+R10+R7 -> 18809.681
B12: Operating Income EBIT | D12: =D6-D11 -> 199.1 | E12: =E6-E11 -> 257 | F12: =F6-F11 -> 355 | G12: =G6-G11 -> 762 | H12: =H6-H11 -> 1364 | I12: =I6-I11 -> 1824 | J12: =J6-J11 -> 2282.91 | K12: =K6-K11 -> 3087.2548 | ... R12: =R6-R11 -> 14805.743
B13: Depreciation | D13: 290.4 | E13: 396 | F13: 352 | G13: 477 | H13: 470 | I13: 618 | X13: Notes for reference
B14: Amortization | D14: 46 | E14: 76 | F14: 81 | G14: 85 | H14: 94 | I14: 120
B15: EBITDA | D15: =D12+D13+D14 -> 535.5 | E15: =E12+E13+E14 -> 729 | F15: =F12+F13+F14 -> 788 | G15: =G12+G13+G14 -> 1324 | H15: =H12+H13+H14 -> 1928 | I15: =I12+I13+I14 -> 2562
B17: Interest Expense | D17: 33 | E17: 28 | F17: 27 | G17: 24 | H17: 23 | I17: 23 | J17: =Assumptions!J166 -> 20.874 | K17: =Assumptions!K166 -> 20.874 | L17: =Assumptions!L166 -> 20.874 | M17: =Assumptions!M166 -> 20.874 | N17: =Assumptions!N166 -> 20.874 | O17: =Assumptions!O166 -> 20.874 | P17: =Assumptions!P166 -> 20.874 | Q17: =Assumptions!Q166 -> 20.874 | R17: =Assumptions!R166 -> 20.874
B18: Interest Income | E18: -20 | F18: -82 | G18: -302 | H18: -419 | I18: -451 | J18: =-Assumptions!J52 -> -310.6 | K18: =-Assumptions!K52 -> -385.90685 | L18: =-Assumptions!L52 -> -472.70477 | M18: =-Assumptions!M52 -> -551.22312 | N18: =-Assumptions!N52 -> -631.55711 | O18: =-Assumptions!O52 -> -692.66878 | P18: =-Assumptions!P52 -> -755.47857 | Q18: =-Assumptions!Q52 -> -813.10803 | R18: =-Assumptions!R52 -> -874.86889
B19: Other Non-Op Loss (inc) | D19: 16 | E19: 0 | F19: 11 | G19: 32 | H19: 22 | I19: -9 | J19: 0 | K19: 0 | L19: 0 | M19: 0 | N19: 0 | O19: 0 | P19: 0 | Q19: 0 | R19: 0
B20: Non Operating Loss (Inc) | D20: =D17+D18+D19 -> 49 | E20: =E17+E18+E19 -> 8 | F20: =F17+F18+F19 -> -44 | G20: =G17+G18+G19 -> -246 | H20: =H17+H18+H19 -> -374 | I20: =I17+I18+I19 -> -437 | J20: =J17+J18+J19 -> -289.726 | K20: =K17+K18+K19 -> -365.03285 | ... R20: =R17+R18+R19 -> -853.99489
B22: Pretax Income | D22: =D12-D20 -> 150.1 | E22: =E12-E20 -> 249 | F22: =F12-F20 -> 399 | G22: =G12-G20 -> 1008 | H22: =H12-H20 -> 1738 | I22: =I12-I20 -> 2261 | J22: =J12-J20 -> 2572.636 | K22: =K12-K20 -> 3452.2876 | ... R22: =R12-R20 -> 15659.738
B24: M&A expenses | D24: 6.1 | E24: 18 | F24: 24 | G24: 38 | H24: 33 | I24: 109
B25: Other Abnormal Expenses | D25: =D26-D24 -> 46.7 | E25: =E26-E24 -> 3 | F25: =F26-F24 -> 0 | G25: =G26-G24 -> 0 | H25: =H26-H24 -> 17 | I25: =I26-I24 -> 141
B26: Abnormal Losses | D26: 52.8 | E26: 21 | F26: 24 | G26: 38 | H26: 50 | I26: 250
B28: Profit before tax | D28: =D22 -> 150.1 | E28: =E22 -> 249 | F28: =F22 -> 399 | G28: =G22 -> 1008 | H28: =H22 -> 1738 | I28: =I22 -> 2261 | J28: =J22-J26 -> 2572.636 | K28: =K22-K26 -> 3452.2876 | L28: =L22-L26 -> 4827.0496 | M28: =M22-M26 -> 5997.6944 | N28: =N22-N26 -> 8594.4663 | O28: =O22-O26 -> 10672.941 | P28: =P22-P26 -> 12381.205 | Q28: =Q22-Q26 -> 13326.616 | R28: =R22-R26 -> 15659.738
B29: Tax expense | D29: 30.7 | E29: 19 | F29: 74 | G29: -723 | H29: 313 | I29: 513 | J29: =0.21*J28 -> 540.25356 | K29: =0.21*K28 -> 724.9804 | L29: =0.21*L28 -> 1013.6804 | M29: =0.21*M28 -> 1259.5158 | N29: =0.21*N28 -> 1804.8379 | O29: =0.21*O28 -> 2241.3176 | P29: =0.21*P28 -> 2600.0531 | Q29: =0.21*Q28 -> 2798.5893 | R29: =0.21*R28 -> 3288.5449
B30: Net income | D30: =D28-D29 -> 119.4 | E30: =E28-E29 -> 230 | F30: =F28-F29 -> 325 | G30: =G28-G29 -> 1731 | H30: =H28-H29 -> 1425 | I30: =I28-I29 -> 1748 | J30: =J28-J29 -> 2032.3824 | K30: =K28-K29 -> 2727.3072 | ... R30: =R28-R29 -> 12371.193
A41: x | B41: End

Sheet BS
A1: =CoName -> ServiceNow
A2: IMPACT INVESTMENT FUND
C4: Hist. | D4: Hist. | E4: Hist. | F4: Hist. | G4: Hist. | H4: Hist. | I4: Proj. | J4: Proj. | K4: Proj. | L4: Proj. | M4: Proj. | N4: Proj. | O4: Proj. | P4: Proj. | Q4: Proj.
A5: Balance sheet | C5: 2020 | D5: =C5+1 -> 2021 | E5: =D5+1 -> 2022 | F5: =E5+1 -> 2023 | G5: =F5+1 -> 2024 | H5: =G5+1 -> 2025 | I5: =H5+1 -> 2026 | J5: =I5+1 -> 2027 | K5: =J5+1 -> 2028 | ... Q5: =P5+1 -> 2034
A8: Balance sheet
I9: =-I49 -> 0
B11: Cash & Cash Equivalents | C11: 1676 | D11: 1728 | E11: 1470 | F11: 1897 | G11: 2304 | H11: 3726 | I11: =H11+CFS!I32 -> 5447.045 | J11: =I11+CFS!J32 -> 7409.3886 | K11: =J11+CFS!K32 -> 10199.963 | L11: =K11+CFS!L32 -> 13607.563 | M11: =L11+CFS!M32 -> 19223.1 | N11: =M11+CFS!N32 -> 27705.276 | O11: =N11+CFS!O32 -> 36814.717 | P11: =O11+CFS!P32 -> 47072.425 | Q11: =P11+CFS!Q32 -> 59673.705
B12: Cash plug | I12: 422 | J12: 1252 | K12: 2140 | L12: 2597 | M12: 3103 | N12: 2405 | O12: 2561 | P12: 2520 | Q12: 994 | R12: for balancing purposes
B13: ST Inv | C13: 1415 | D13: 1576 | E13: 2810 | F13: 2980 | G13: 3458 | H13: 2558 | I13: =Assumptions!J69 -> 2950.7 | J13: =Assumptions!K69 -> 3666.1151 | K13: =Assumptions!L69 -> 4490.6953 | L13: =Assumptions!M69 -> 5236.6196 | M13: =Assumptions!N69 -> 5999.7925 | N13: =Assumptions!O69 -> 6580.3534 | O13: =Assumptions!P69 -> 7177.0464 | P13: =Assumptions!Q69 -> 7724.5263 | Q13: =Assumptions!R69 -> 8311.2544
B14: Accounts receivable | C14: 1009 | D14: 1390 | E14: 1725 | F14: 2036 | G14: 2240 | H14: 2627 | I14: =Assumptions!J66 -> 3431.7046 | J14: =Assumptions!K66 -> 4263.7421 | K14: =Assumptions!L66 -> 5222.7403 | L14: =Assumptions!M66 -> 6090.2605 | M14: =Assumptions!N66 -> 6977.8411 | N14: =Assumptions!O66 -> 7653.0413 | O14: =Assumptions!P66 -> 8347.0035 | P14: =Assumptions!Q66 -> 8983.7301 | Q14: =Assumptions!R66 -> 9666.103
B15: Prepaid expenses | C15: 191 | D15: 223 | E15: 280 | F15: 403 | G15: 668 | H15: 970 | I15: =Assumptions!J75 -> 1098.567 | J15: =Assumptions!K75 -> 1322.2674 | K15: =Assumptions!L75 -> 1619.671 | L15: =Assumptions!M75 -> 1888.7055 | M15: =Assumptions!N75 -> 1884.7403 | N15: =Assumptions!O75 -> 1913.9947 | O15: =Assumptions!P75 -> 2004.0498 | P15: =Assumptions!Q75 -> 2156.9228 | Q15: =Assumptions!R75 -> 2127.3589
B16: Current portion of def commisions, net | C16: 231 | D16: 302 | E16: 369 | F16: 461 | G16: 518 | H16: 590 | I16: 687.5 | J16: 780.3 | K16: 897.3 | L16: 1031.9 | M16: 1186.7 | N16: 1364.7 | O16: 1569.4 | P16: 1804.82 | Q16: 2075.55 | R16: hardcoded to avoid circular ref
B17: Total current assets | C17: =C11+C13+C14+C16+C15 -> 4522 | D17: =D11+D13+D14+D16+D15 -> 5219 | E17: =E11+E13+E14+E16+E15 -> 6654 | F17: =F11+F13+F14+F16+F15 -> 7777 | G17: =G11+G13+G14+G16+G15 -> 9188 | H17: =H11+H13+H14+H16+H15 -> 10471 | I17: =SUM(I11:I16) -> 14037.517 | J17: =SUM(J11:J16) -> 18693.813 | K17: =SUM(K11:K16) -> 24570.369 | L17: =SUM(L11:L16) -> 30452.048 | M17: =SUM(M11:M16) -> 38375.174 | N17: =SUM(N11:N16) -> 47622.365 | O17: =SUM(O11:O16) -> 58473.216 | P17: =SUM(P11:P16) -> 70262.424 | Q17: =SUM(Q11:Q16) -> 82847.971
B19: PPE Net | C19: 659 | D19: 766 | E19: 1053 | F19: 1358 | G19: 1763 | H19: 2289 | I19: =Assumptions!J145 -> 2636.174 | J19: =Assumptions!K145 -> 3125.3318 | K19: =Assumptions!L145 -> 3797.2714 | L19: =Assumptions!M145 -> 4283.5892 | M19: =Assumptions!N145 -> 4636.1684 | N19: =Assumptions!O145 -> 5137.8775 | O19: =Assumptions!P145 -> 5331.0743 | P19: =Assumptions!Q145 -> 5604.5899 | Q19: =Assumptions!R145 -> 5942.2474
B20: LT Investments | C20: 1468 | D20: 1630 | E20: 2117 | F20: 3203 | G20: 4583 | H20: 5313 | I20: =H20 -> 5313 | J20: =I20 -> 5313 | K20: =J20 -> 5313 | L20: =K20 -> 5313 | M20: =L20 -> 5313 | N20: =M20 -> 5313 | O20: =N20 -> 5313 | P20: =O20 -> 5313 | Q20: =P20 -> 5313
B21: Ingantible Assets,net | C21: 153 | D21: 287 | E21: 232 | F21: 224 | G21: 209 | H21: 1121 | I21: =Assumptions!J151 -> 1163.4454 | J21: =Assumptions!K151 -> 1286.9308 | K21: =Assumptions!L151 -> 1480.821 | L21: =Assumptions!M151 -> 1713.0482 | M21: =Assumptions!N151 -> 1974.0557 | N21: =Assumptions!O151 -> 2230.9375 | O21: =Assumptions!P151 -> 2487.089 | P21: =Assumptions!Q151 -> 2736.2601 | Q21: =Assumptions!R151 -> 2985.7682
B22: Goodwill | C22: 241 | D22: 777 | E22: 824 | F22: 1231 | G22: 1273 | H22: 3578 | I22: =H22 -> 3578 | J22: =I22 -> 3578 | K22: =J22 -> 3578 | L22: =K22 -> 3578 | M22: =L22 -> 3578 | N22: =M22 -> 3578 | O22: =N22 -> 3578 | P22: =O22 -> 3578 | Q22: =P22 -> 3578
B23: Other LT Assets (Deferred tax assets + Deferred commisions + Op Lease + Other) | C23: 1672 | D23: 2118 | E23: 2419 | F23: 3594 | G23: 3367 | H23: 3266 | I23: =Assumptions!J78 -> 3820.38 | J23: =Assumptions!K78 -> 4746.6542 | K23: =Assumptions!L78 -> 5814.2686 | L23: =Assumptions!M78 -> 6780.0443 | M23: =Assumptions!N78 -> 7768.1524 | N23: =Assumptions!O78 -> 8519.826 | O23: =Assumptions!P78 -> 9292.3864 | P23: =Assumptions!Q78 -> 10001.229 | Q23: =Assumptions!R78 -> 10760.887
B25: Total non-current assets | C25: =C19+C20+C21+C23+C22 -> 4193 | D25: =D19+D20+D21+D23+D22 -> 5578 | E25: =E19+E20+E21+E23+E22 -> 6645 | F25: =F19+F20+F21+F23+F22 -> 9610 | G25: =G19+G20+G21+G23+G22 -> 11195 | H25: =H19+H20+H21+H23+H22 -> 15567 | I25: =SUM(I19:I23) -> 16510.999 | J25: =SUM(J19:J23) -> 18049.917 | K25: =SUM(K19:K23) -> 19983.361 | L25: =SUM(L19:L23) -> 21667.682 | M25: =SUM(M19:M23) -> 23269.377 | N25: =SUM(N19:N23) -> 24779.641 | O25: =SUM(O19:O23) -> 26001.55 | P25: =SUM(P19:P23) -> 27233.079 | Q25: =SUM(Q19:Q23) -> 28579.903
B27: TOTAL ASSETS | C27: =C17+C25 -> 8715 | D27: =D17+D25 -> 10797 | E27: =E17+E25 -> 13299 | F27: =F17+F25 -> 17387 | G27: =G17+G25 -> 20383 | H27: =H17+H25 -> 26038 | I27: =I17+I25 -> 30548.516 | J27: =J17+J25 -> 36743.73 | ... Q27: =Q17+Q25 -> 111427.87
B29: Current debt | C29: 0 | D29: 92 | E29: 0 | F29: 0 | G29: 0 | H29: 0 | I29: =H29 -> 0 | J29: =I29 -> 0 | K29: =J29 -> 0 | L29: =K29 -> 0 | M29: =L29 -> 0 | N29: =M29 -> 0 | O29: =N29 -> 0 | P29: =O29 -> 0 | Q29: =P29 -> 0
B30: Accounts payable | C30: 34 | D30: 89 | E30: 274 | F30: 126 | G30: 68 | H30: 204 | I30: =Assumptions!J81 -> 194.92054 | J30: =Assumptions!K81 -> 247.44499 | K30: =Assumptions!L81 -> 296.50389 | L30: =Assumptions!M81 -> 348.37574 | M30: =Assumptions!N81 -> 400.0827 | N30: =Assumptions!O81 -> 437.01414 | O30: =Assumptions!P81 -> 477.56438 | P30: =Assumptions!Q81 -> 514.02919 | Q30: =Assumptions!R81 -> 552.69163
B31: Deferred Revenue | C31: 2963 | D31: 3836 | E31: 4660 | F31: 5785 | G31: 6819 | H31: 8314 | I31: =Assumptions!J25 -> 10067.872 | J31: =Assumptions!K25 -> 12719.365 | K31: =Assumptions!L25 -> 15813.778 | L31: =Assumptions!M25 -> 18343.982 | M31: =Assumptions!N25 -> 21132.268 | N31: =Assumptions!O25 -> 23891.203 | O31: =Assumptions!P25 -> 26514.392 | P31: =Assumptions!Q25 -> 29033.259 | Q31: =Assumptions!R25 -> 30775.255
B32: Other current liabilities (acrrued expenses and other) | C32: 740 | D32: 932 | E32: 1071 | F32: 1454 | G32: 1471 | H32: 1925 | I32: =Assumptions!J84 -> 2096.2328 | J32: =Assumptions!K84 -> 2518.8347 | K32: =Assumptions!L84 -> 2979.4981 | L32: =Assumptions!M84 -> 3422.1338 | M32: =Assumptions!N84 -> 3506.217 | N32: =Assumptions!O84 -> 3625.707 | O32: =Assumptions!P84 -> 3763.2225 | P32: =Assumptions!Q84 -> 4050.0244 | Q32: =Assumptions!R84 -> 4075.9363
B33: Total current liabilities | C33: =C29+C30+C31+C32 -> 3737 | D33: =D29+D30+D31+D32 -> 4949 | E33: =E29+E30+E31+E32 -> 6005 | F33: =F29+F30+F31+F32 -> 7365 | G33: =G29+G30+G31+G32 -> 8358 | H33: =H29+H30+H31+H32 -> 10443 | I33: =I29+I30+I31+I32 -> 12359.026 | J33: =J29+J30+J31+J32 -> 15485.645 | ... Q33: =Q29+Q30+Q31+Q32 -> 35403.883
B35: Long-term debt, net | C35: 1640 | D35: 1484 | E35: 1486 | F35: 1488 | G35: 1489 | H35: 1491 | I35: =Assumptions!J164 -> 1491 | J35: =Assumptions!K164 -> 1491 | K35: =Assumptions!L164 -> 1491 | L35: =Assumptions!M164 -> 1491 | M35: =Assumptions!N164 -> 1491 | N35: =Assumptions!O164 -> 1491 | O35: =Assumptions!P164 -> 1491 | P35: =Assumptions!Q164 -> 1491 | Q35: =Assumptions!R164 -> 1491
B36: Other long-term liabilities | C36: 504 | D36: 670 | E36: 776 | F36: 906 | G36: 927 | H36: 1140 | I36: =Assumptions!J90 -> 1404.1391 | J36: =Assumptions!K90 -> 1744.5811 | K36: =Assumptions!L90 -> 2136.9712 | L36: =Assumptions!M90 -> 2491.9316 | M36: =Assumptions!N90 -> 2855.0999 | N36: =Assumptions!O90 -> 3131.3694 | O36: =Assumptions!P90 -> 3415.3156 | P36: =Assumptions!Q90 -> 3675.8429 | Q36: =Assumptions!R90 -> 3955.0471
B37: Total non-current liabilities | C37: =C35+C36 -> 2144 | D37: =D35+D36 -> 2154 | E37: =E35+E36 -> 2262 | F37: =F35+F36 -> 2394 | G37: =G35+G36 -> 2416 | H37: =H35+H36 -> 2631 | I37: =I35+I36 -> 2895.1391 | J37: =J35+J36 -> 3235.5811 | ... Q37: =Q35+Q36 -> 5446.0471
B39: TOTAL LIABILITIES | C39: =C33+C37 -> 5881 | D39: =D33+D37 -> 7103 | E39: =E33+E37 -> 8267 | F39: =F33+F37 -> 9759 | G39: =G33+G37 -> 10774 | H39: =H33+H37 -> 13074 | I39: =I33+I37 -> 15254.165 | J39: =J33+J37 -> 18721.226 | ... Q39: =Q33+Q37 -> 40849.93
B41: Additional Paid in Capital | C41: 2974 | D41: 3664 | E41: 4796 | F41: 6131 | G41: 7401 | H41: 10747 | I41: =H41+CFS!I8 -> 13045.44 | J41: =I41+CFS!J8 -> 15650.311 | K41: =J41+CFS!K8 -> 18841.068 | L41: =K41+CFS!L8 -> 21597.184 | M41: =L41+CFS!M8 -> 23807.634 | N41: =M41+CFS!N8 -> 25539.306 | O41: =N41+CFS!O8 -> 26861.393 | P41: =O41+CFS!P8 -> 27471.224 | Q41: =P41+CFS!Q8 -> 27908.659
B42: Treasury Stock | F42: -535 | G42: -1218 | H42: -3044 | I42: =H42+CFS!I26 -> -5044 | J42: =I42+CFS!J26 -> -7648.8712 | K42: =J42+CFS!K26 -> -10839.628 | L42: =K42+CFS!L26 -> -14146.967 | M42: =L42+CFS!M26 -> -16910.029 | N42: =M42+CFS!N26 -> -19507.537 | O42: =N42+CFS!O26 -> -21622.877 | P42: =O42+CFS!P26 -> -22842.539 | Q42: =P42+CFS!Q26 -> -23804.895
B43: RE (accumulated deficit) | C43: -234 | D43: -4 | E43: 338 | F43: 2069 | G43: 3494 | H43: 5242 | I43: =Assumptions!J158 -> 7274.3824 | J43: =Assumptions!K158 -> 10001.69 | K43: =Assumptions!L158 -> 13815.059 | L43: =Assumptions!M158 -> 18553.237 | M43: =Assumptions!N158 -> 25342.866 | N43: =Assumptions!O158 -> 33774.489 | O43: =Assumptions!P158 -> 43555.641 | P43: =Assumptions!Q158 -> 54083.668 | Q43: =Assumptions!R158 -> 66454.86
B44: Other | C44: 94 | D44: 34 | E44: -102 | F44: -37 | G44: -68 | H44: 19 | I44: =H44 -> 19 | J44: =I44 -> 19 | K44: =J44 -> 19 | L44: =K44 -> 19 | M44: =L44 -> 19 | N44: =M44 -> 19 | O44: =N44 -> 19 | P44: =O44 -> 19 | Q44: =P44 -> 19
B45: Total Equity | C45: =C41+C42+C43+C44 -> 2834 | D45: =D41+D42+D43+D44 -> 3694 | E45: =E41+E42+E43+E44 -> 5032 | F45: =F41+F42+F43+F44 -> 7628 | G45: =G41+G42+G43+G44 -> 9609 | H45: =H41+H42+H43+H44 -> 12964 | I45: =I41+I42+I43+I44 -> 15294.822 | J45: =J41+J42+J43+J44 -> 18022.13 | ... Q45: =Q41+Q42+Q43+Q44 -> 70577.624
B47: TOTAL LIABILITIES & EQUITY | C47: =C33+C37+C45 -> 8715 | D47: =D33+D37+D45 -> 10797 | E47: =E33+E37+E45 -> 13299 | F47: =F33+F37+F45 -> 17387 | G47: =G33+G37+G45 -> 20383 | H47: =H33+H37+H45 -> 26038 | I47: =I33+I37+I45 -> 30548.987 | J47: =J33+J37+J45 -> 36743.356 | ... Q47: =Q33+Q37+Q45 -> 111427.55
A51: x | B51: End

Sheet CFS
A1: =CoName -> ServiceNow | C1: Hist. | D1: Hist. | E1: Hist. | F1: Hist. | G1: Hist. | H1: Hist. | I1: Proj. | J1: Proj. | K1: Proj. | L1: Proj. | M1: Proj. | N1: Proj. | O1: Proj. | P1: Proj. | Q1: Proj.
A2: Cash flow statement (in millions USD) | C2: 2020 | D2: =C2+1 -> 2021 | E2: =D2+1 -> 2022 | F2: =E2+1 -> 2023 | G2: =F2+1 -> 2024 | H2: =G2+1 -> 2025 | I2: =H2+1 -> 2026 | J2: =I2+1 -> 2027 | K2: =J2+1 -> 2028 | ... Q2: =P2+1 -> 2034
B4: Net Income | C4: =IS!D30 -> 119.4 | D4: =IS!E30 -> 230 | E4: =IS!F30 -> 325 | F4: =IS!G30 -> 1731 | G4: =IS!H30 -> 1425 | H4: =IS!I30 -> 1748 | I4: =IS!J30 -> 2032.3824 | J4: =IS!K30 -> 2727.3072 | ... Q4: =IS!R30 -> 12371.193
B5: Depreciation | C5: =IS!D13 -> 290.4 | D5: =IS!E13 -> 396 | E5: =IS!F13 -> 352 | F5: =IS!G13 -> 477 | G5: =IS!H13 -> 470 | H5: =IS!I13 -> 618 | I5: =Assumptions!J113 -> 831.57529 | J5: =Assumptions!K113 -> 1054.4696 | K5: =Assumptions!L113 -> 1218.8794 | L5: =Assumptions!M113 -> 1442.9631 | M5: =Assumptions!N113 -> 1542.0921 | N5: =Assumptions!O113 -> 1576.2973 | O5: =Assumptions!P113 -> 1695.4996 | P5: =Assumptions!Q113 -> 1759.2545 | Q5: =Assumptions!R113 -> 1849.5147
B6: Amortization on Assets | C6: =IS!D14 -> 46 | D6: =IS!E14 -> 76 | E6: =IS!F14 -> 81 | F6: =IS!G14 -> 85 | G6: =IS!H14 -> 94 | H6: =IS!I14 -> 120 | I6: =Assumptions!J117 -> 345.80463 | J6: =Assumptions!K117 -> 358.89812 | K6: =Assumptions!L117 -> 396.99075 | L6: =Assumptions!M117 -> 456.80175 | M6: =Assumptions!N117 -> 528.43888 | N6: =Assumptions!O117 -> 608.95414 | O6: =Assumptions!P117 -> 688.19671 | P6: =Assumptions!Q117 -> 767.214 | Q6: =Assumptions!R117 -> 844.07795
B7: Amortization of deferred commisions | C7: 218 | D7: 294 | E7: 358 | F7: 459 | G7: 550 | H7: 621 | I7: =Assumptions!J125 -> 701.16545 | J7: =Assumptions!K125 -> 791.67954 | K7: =Assumptions!L125 -> 893.87817 | L7: =Assumptions!M125 -> 1009.2697 | M7: =Assumptions!N125 -> 1139.5573 | N7: =Assumptions!O125 -> 1286.6637 | O7: =Assumptions!P125 -> 1452.7603 | P7: =Assumptions!Q125 -> 1640.2985 | Q7: =Assumptions!R125 -> 1852.0461
B8: SBC | C8: 870 | D8: 1131 | E8: 1401 | F8: 1604 | G8: 1746 | H8: 1955 | I8: =0.148*IS!J4 -> 2298.44 | J8: =0.135*IS!K4 -> 2604.8712 | K8: =0.135*IS!L4 -> 3190.7572 | L8: =0.1*IS!M4 -> 2756.1156 | M8: =0.07*IS!N4 -> 2210.4499 | N8: =0.05*IS!O4 -> 1731.6719 | O8: =0.035*IS!P4 -> 1322.0875 | P8: =0.015*IS!Q4 -> 609.83102 | Q8: =0.01*IS!R4 -> 437.43444
B9: Other Non Cash Items | C9: 246.3 | D9: 33 | E9: 32 | F9: -851 | G9: 47 | H9: 353
B10: Change in Net Working Capital | C10: -2.5 | D10: 31 | E10: 174 | F10: -107 | G10: -65 | H10: 29 | I10: =Assumptions!J109 -> -151.32352 | J10: =Assumptions!K109 -> -174 | K10: =Assumptions!L109 -> -280.84335 | L10: =Assumptions!M109 -> -300.0804 | M10: =Assumptions!N109 -> -377.44864 | N10: =Assumptions!O109 -> 1158.3152 | O10: =Assumptions!P109 -> -111.87092 | P10: =Assumptions!Q109 -> -8.0985363 | Q10: =Assumptions!R109 -> 260.12793
B11: Cash Flow from Operating Activities | C11: =C4+C5+C6+C8+C9+C10+C7 -> 1787.6 | D11: =D4+D5+D6+D8+D9+D10+D7 -> 2191 | E11: =E4+E5+E6+E8+E9+E10+E7 -> 2723 | F11: =F4+F5+F6+F8+F9+F10+F7 -> 3398 | G11: =G4+G5+G6+G8+G9+G10+G7 -> 4267 | H11: =H4+H5+H6+H8+H9+H10+H7 -> 5444 | I11: =I4+I5+I6+I8+I9+I10+I7 -> 6058.0443 | J11: =J4+J5+J6+J8+J9+J10+J7 -> 7363.2257 | ... Q11: =Q4+Q5+Q6+Q8+Q9+Q10+Q7 -> 17614.394
B14: Capex | C14: -419 | D14: -392 | E14: -550 | F14: -694 | G14: -852 | H14: -868 | I14: =-Assumptions!J134 -> -1178.7492 | J14: =-Assumptions!K134 -> -1543.6274 | K14: =-Assumptions!L134 -> -1890.8191 | L14: =-Assumptions!M134 -> -1929.2809 | M14: =-Assumptions!N134 -> -1894.6713 | N14: =-Assumptions!O134 -> -2078.0063 | O14: =-Assumptions!P134 -> -1888.6964 | P14: =-Assumptions!Q134 -> -2032.7701 | Q14: =-Assumptions!R134 -> -2187.1722
B15: Capex on Intangible assets | C15: -107 | D15: -785 | E15: -91 | F15: -279 | G15: -113 | H15: -1084 | I15: =-Assumptions!J136 -> -388.25 | J15: =-Assumptions!K136 -> -482.38356 | K15: =-Assumptions!L136 -> -590.88096 | L15: =-Assumptions!M136 -> -689.0289 | M15: =-Assumptions!N136 -> -789.44639 | N15: =-Assumptions!O136 -> -865.83597 | O15: =-Assumptions!P136 -> -944.34822 | P15: =-Assumptions!Q136 -> -1016.385 | Q15: =-Assumptions!R136 -> -1093.5861
B16: Minority Investments
B17: Purchase of strategic investments | C17: -12 | D17: -71 | E17: -167 | F17: -75 | G17: -181 | H17: -1056
B18: Purchase of Other Intangibles | C18: -13 | D18: -7 | E18: 0 | F18: -3 | G18: -40 | H18: -43
B19: Other Investing Activities, net | C19: -956 | D19: -352 | E19: -1775 | F19: -1116 | G19: -1315 | H19: 1362
B20: Cash Flow from Investing Activities | C20: =C14+C15+C17+C19+C18 -> -1507 | D20: =D14+D15+D17+D19+D18 -> -1607 | E20: =E14+E15+E17+E19 -> -2583 | F20: =F14+F15+F17+F19+F18 -> -2167 | G20: =G14+G15+G17+G19+G18 -> -2501 | H20: =H14+H15+H17+H19+H18 -> -1689 | I20: =I14+I15+I17+I19+I18 -> -1566.9992 | J20: =J14+J15+J17+J19+J18 -> -2026.011 | K20: =K14+K15+K17+K19+K18 -> -2481.7 | L20: =L14+L15+L17+L19+L18 -> -2618.3098 | M20: =M14+M15+M17+M19+M18 -> -2684.1177 | ... Q20: =Q14+Q15+Q17+Q19+Q18 -> -3280.7583
B22: Cash from Debt | C22: 2587.2 | D22: 0 | E22: 0 | F22: 0 | G22: 0 | H22: 0
B23: Repayment of Debt | C23: -1627.7 | D23: -61 | E23: -94 | F23: 0 | G23: 0 | H23: 0
B24: Dividends Paid on Common Stock
B25: Proceeds from Employee stock plan | C25: 146 | D25: 167 | E25: 177 | F25: 194 | G25: 237 | H25: 270
B26: Repurchase of Common Stock | C26: 0 | D26: 0 | E26: 0 | F26: -538 | G26: -696 | H26: -1840 | I26: =-2000 -> -2000 | J26: =-J8*1 -> -2604.8712 | K26: =-K8*1 -> -3190.7572 | L26: =-L8*1.2 -> -3307.3387 | M26: =-M8*1.25 -> -2763.0624 | N26: =-N8*1.5 -> -2597.5079 | O26: =-O8*1.6 -> -2115.34 | P26: =-P8*2 -> -1219.662 | Q26: =-Q8*2.2 -> -962.35577
B27: Other Financing Activities | C27: -508.6 | D27: -612 | E27: -427 | F27: -459 | G27: -884 | H27: -770 | I27: =H27 -> -770 | J27: =I27 -> -770 | K27: =J27 -> -770 | L27: =K27 -> -770 | M27: =L27 -> -770 | N27: =M27 -> -770 | O27: =N27 -> -770 | P27: =O27 -> -770 | Q27: =P27 -> -770 | R27: taxes paid in settlement of equity awards
B28: Cash Flow from Financing Activities | C28: =C22+C23+C24+C25+C26+C27 -> 596.9 | D28: =D22+D23+D24+D25+D26+D27 -> -506 | E28: =E22+E23+E24+E25+E26+E27 -> -344 | F28: =F22+F23+F24+F25+F26+F27 -> -803 | G28: =G22+G23+G24+G25+G26+G27 -> -1343 | H28: =H22+H23+H24+H25+H26+H27 -> -2340 | I28: =I22+I23+I24+I25+I26+I27 -> -2770 | J28: =J22+J23+J24+J25+J26+J27 -> -3374.8712 | ... Q28: =Q22+Q23+Q24+Q25+Q26+Q27 -> -1732.3558
B30: Effect of Foreign Exchange Rates | C30: 25.1 | D30: -25 | E30: -53 | F30: 1 | G30: -17 | H30: 7
B32: Net Change in Cash | C32: =C11+C20+C28+C30 -> 902.6 | D32: =D11+D20+D28+D30 -> 53 | E32: =E11+E20+E28+E30 -> -257 | F32: =F11+F20+F28+F30 -> 429 | G32: =G11+G20+G28+G30 -> 406 | H32: =H11+H20+H28+H30 -> 1422 | I32: =I11+I20+I28+I30 -> 1721.045 | J32: =J11+J20+J28+J30 -> 1962.3435 | ... Q32: =Q11+Q20+Q28+Q30 -> 12601.28
A40: x | B40: End

Sheet DCF
B1: IMPACT INVESTMENT FUND
B2: ServiceNow
B3: Financial Model
B4: DCF Valuation
B6: Input Assumptions
B11: WACC
B12: Expected Market Return | C12: 0.1039
B13: Risk Free Rate | C13: 0.0406
B14: Market Risk Premium | C14: =C12-C13 -> 0.0633
B15: Beta | C15: 1.372
B16: Cost of Equity | C16: =C13+(C14*C15) -> 0.1274476
B17: Pre-Tax Cost of Debt | C17: 0.0406
B18: Effective Tax Rate | C18: 0.21
B19: After Tax Cost Of Debt | C19: =C17*(1-C18) -> 0.032074
B20: Weight of Equity | C20: 0.985
B21: Weight of Debt | C21: 0.015
B22: WACC | C22: =(C20*C16)+(C21*C19) -> 0.126017
B24: Unlevered Free Cash Flow Calculation
B26: Years | J26: 2026E | K26: 2027E | L26: 2028E | M26: 2029E | N26: 2030E | O26: 2031E | P26: 2032E | Q26: 2033E | R26: 2034E
B28: EBIT | J28: =IS!J12 -> 2282.91 | K28: =IS!K12 -> 3087.2548 | L28: =IS!L12 -> 4375.2188 | M28: =IS!M12 -> 5467.3453 | N28: =IS!N12 -> 7983.7832 | O28: =IS!O12 -> 10001.146 | P28: =IS!P12 -> 11646.601 | Q28: =IS!Q12 -> 12534.382 | R28: =IS!R12 -> 14805.743
B29: Times: (1 - Tax Rate) | J29: =1-$C$18 -> 0.79 | K29: =1-$C$18 -> 0.79 | L29: =1-$C$18 -> 0.79 | M29: =1-$C$18 -> 0.79 | N29: =1-$C$18 -> 0.79 | O29: =1-$C$18 -> 0.79 | P29: =1-$C$18 -> 0.79 | Q29: =1-$C$18 -> 0.79 | R29: =1-$C$18 -> 0.79
B30: Equals: NOPAT | J30: =J28*J29 -> 1803.4989 | K30: =K28*K29 -> 2438.9313 | L30: =L28*L29 -> 3456.4229 | M30: =M28*M29 -> 4319.2028 | N30: =N28*N29 -> 6307.1887 | O30: =O28*O29 -> 7900.9056 | P30: =P28*P29 -> 9200.8144 | Q30: =Q28*Q29 -> 9902.1615 | R30: =R28*R29 -> 11696.537
B31: Plus: Depreciation | J31: =Assumptions!J113 -> 831.57529 | K31: =Assumptions!K113 -> 1054.4696 | L31: =Assumptions!L113 -> 1218.8794 | M31: =Assumptions!M113 -> 1442.9631 | N31: =Assumptions!N113 -> 1542.0921 | O31: =Assumptions!O113 -> 1576.2973 | P31: =Assumptions!P113 -> 1695.4996 | Q31: =Assumptions!Q113 -> 1759.2545 | R31: =Assumptions!R113 -> 1849.5147
B32: Plus: Amortization | J32: =Assumptions!J117 -> 345.80463 | K32: =Assumptions!K117 -> 358.89812 | L32: =Assumptions!L117 -> 396.99075 | M32: =Assumptions!M117 -> 456.80175 | N32: =Assumptions!N117 -> 528.43888 | O32: =Assumptions!O117 -> 608.95414 | P32: =Assumptions!P117 -> 688.19671 | Q32: =Assumptions!Q117 -> 767.214 | R32: =Assumptions!R117 -> 844.07795
B33: Plus: Amortization of Commissions | J33: 665.96 | K33: 744.71 | L33: 800 | M33: 850 | N33: 900 | O33: 1050 | P33: 1100 | Q33: 1100 | R33: 1100
B34: Plus: Change In Working Capital | J34: =Assumptions!J109 -> -151.32352 | K34: =Assumptions!K109 -> -174 | L34: =Assumptions!L109 -> -280.84335 | M34: =Assumptions!M109 -> -300.0804 | N34: =Assumptions!N109 -> -377.44864 | O34: =Assumptions!O109 -> 1158.3152 | P34: =Assumptions!P109 -> -111.87092 | Q34: =Assumptions!Q109 -> -8.0985363 | R34: =Assumptions!R109 -> 260.12793
B35: Less: Capital Expenditures | J35: =-Assumptions!J134 -> -1178.7492 | K35: =-Assumptions!K134 -> -1543.6274 | L35: =-Assumptions!L134 -> -1890.8191 | M35: =-Assumptions!M134 -> -1929.2809 | N35: =-Assumptions!N134 -> -1894.6713 | O35: =-Assumptions!O134 -> -2078.0063 | P35: =-Assumptions!P134 -> -1888.6964 | Q35: =-Assumptions!Q134 -> -2032.7701 | R35: =-Assumptions!R134 -> -2187.1722
B36: Less: Capital Expenditures on Intangibles | J36: =-Assumptions!J136 -> -388.25 | K36: =-Assumptions!K136 -> -482.38356 | L36: =-Assumptions!L136 -> -590.88096 | M36: =-Assumptions!M136 -> -689.0289 | N36: =-Assumptions!N136 -> -789.44639 | O36: =-Assumptions!O136 -> -865.83597 | P36: =-Assumptions!P136 -> -944.34822 | Q36: =-Assumptions!Q136 -> -1016.385 | R36: =-Assumptions!R136 -> -1093.5861
B37: Equals: Unlevered Free Cash Flow | J37: =J30+J31+J32+J34-J35-J36+J33 -> 5062.5145 | K37: =K30+K31+K32+K34-K35-K36+K33 -> 6449.0199 | L37: =L30+L31+L32+L34-L35-L36+L33 -> 8073.1497 | M37: =M30+M31+M32+M34-M35-M36+M33 -> 9387.1971 | N37: =N30+N31+N32+N34-N35-N36+N33 -> 11584.389 | O37: =O30+O31+O32+O34-O35-O36+O33 -> 15238.315 | P37: =P30+P31+P32+P34-P35-P36+P33 -> 15405.684 | Q37: =Q30+Q31+Q32+Q34-Q35-Q36+Q33 -> 16569.687 | R37: =R30+R31+R32+R34-R35-R36+R33 -> 19031.016
B38: Discount Period | J38: 1 | K38: 2 | L38: 3 | M38: 4 | N38: 5 | O38: 6 | P38: 7 | Q38: 8 | R38: 9
B39: Discount Factor | J39: =1/(1+$C$22)^J38 -> 0.88808606 | K39: =1/(1+$C$22)^K38 -> 0.78869685 | L39: =1/(1+$C$22)^L38 -> 0.70043068 | M39: =1/(1+$C$22)^M38 -> 0.62204273 | N39: =1/(1+$C$22)^N38 -> 0.55242748 | O39: =1/(1+$C$22)^O38 -> 0.49060314 | P39: =1/(1+$C$22)^P38 -> 0.43569781 | Q39: =1/(1+$C$22)^Q38 -> 0.38693715 | R39: =1/(1+$C$22)^R38 -> 0.34363349
B40: Equals: Present Value of Unlevered Free Cash Flow | J40: =J37*J39 -> 4495.9486 | K40: =K37*K39 -> 5086.3217 | L40: =L37*L39 -> 5654.6817 | M40: =M37*M39 -> 5839.2377 | N40: =N37*N39 -> 6399.5347 | O40: =O37*O39 -> 7475.965 | P40: =P37*P39 -> 6712.223 | Q40: =Q37*Q39 -> 6411.4274 | R40: =R37*R39 -> 6539.6944
B41: Forecasted EBITDA | J41: =J28+J31+J32 -> 3460.2899 | K41: =K28+K31+K32 -> 4500.6225 | L41: =L28+L31+L32 -> 5991.0889 | M41: =M28+M31+M32 -> 7367.1102 | N41: =N28+N31+N32 -> 10054.314 | O41: =O28+O31+O32 -> 12186.398 | P41: =P28+P31+P32 -> 14030.297 | Q41: =Q28+Q31+Q32 -> 15060.85 | R41: =R28+R31+R32 -> 17499.335
B44: Discounted Cash Flow Valuation
B46: Perpetuity Growth Method | F46: FCFF Fair Value Multiple Method - EV/EBITDA
B47: Perpetuity Growth Rate | C47: 0.03 | F47: EV/EBITDA Multiple | G47: 20
B48: Present Value of Terminal Value | C48: =(R37*(1+C47)/(C22-C47))/(1+C22)^R38 -> 70153.051 | F48: Last Forecast EBITDA | G48: =R41 -> 17499.335
B49: % of EV | C49: =C48/C52 -> 0.56226759 | F49: Terminal Value | G49: =G47*G48 -> 349986.71
B50: Plus: Present Value of Forecast FCF | C50: =SUM(J40:R40) -> 54615.034 | F50: PV of Terminal Value | G50: =R39*G49 -> 120267.15
B51: % of EV | C51: =C50/C52 -> 0.43773241 | F51: Terminal Value as a % of EV | G51: =G50/G54 -> 0.68770385
...

Sheet Comps
O4: Company | P4: Column2 | Q4: M.Cap | R4: Price | S4: NTM EPS | T4: Column3 | U4: NTM NI | V4: Rev | W4: NTM Rev | X4: EV | Y4: EV/Rev | Z4: Rev Growth | AA4: (EV/Rev)/RG% | AB4: EV4 | AC4: EBITDA | AD4: EV/EBITDA | AE4: M.Cap5 | AF4: FCF | AG4: P/FCF
A6: MSFT | B6: Rev | C6: NTM Rev | D6: Rev G% | E6: CY EPS | F6: NTM EPS | G6: EV | H6: EBITDA | I6: LTM M.Cap | J6: FCF | K6: Price | O6: ServiceNow | P6: NOW | Q6: 160432 | R6: 114 | S6: 4.19 | U6: =IS!J30 -> 2032.3824 | V6: 13242.2 | W6: =V6+V6*(Z6/100) -> 15493.374 | X6: 106801.3 | Y6: =X6/V6 -> 8.0652233 | Z6: 17 | AA6: =Y6/Z6 -> 0.4744249 | AB6: 110744 | AC6: =IS!I15 -> 2562 | AD6: =AB6/AC6 -> 43.225605 | AE6: 118396 | AF6: 4576 | AG6: =AE6/AF6 -> 25.873252
A7: Total MSFT | B7: 281724 | E7: 13.64 | F7: 16.9 | G7: 3033250.4 | H7: 191230 | I7: 2999434 | J7: 71611 | K7: 403 | O7: Salesforce | P7: CRM | Q7: 328715 | R7: 192.95 | S7: 13.14 | V7: 41525 | W7: =V7+V7*(Z7/100) -> 46134.275 | X7: 188405.2 | Y7: =X7/V7 -> 4.5371511 | Z7: 11.1 | AA7: =Y7/Z7 -> 0.40875235 | AB7: 189100 | AC7: 13306 | AD7: =AB7/AC7 -> 14.211634 | AE7: 180954.2 | AF7: 14402 | AG7: =AE7/AF7 -> 12.564519
A8: MSFT P&B Rev | B8: 120810 | C8: 138434 | D8: =(C8-B8)/B8 -> 0.14588196 | E8: =E7*B9 -> 5.8491588 | F8: =F7*B9 -> 7.2471248 | G8: =G7*$B$9 -> 1300730.4 | H8: =H7*$B$9 -> 82004.005 | I8: =I7*B9 -> 1286229.2 | J8: =J7*$B$9 -> 30708.512 | K8: =K7*$B$9 -> 172.81605 | O8: Microsoft BP | P8: MSFT (PB) | R8: =K12 -> 136.74512 | S8: =F12 -> 5.7344727 | V8: =B12 -> 95594 | W8: =V8+V8*(Z8/100) -> 109731 | X8: =G12 -> 1029236.2 | Y8: =X8/V8 -> 10.766745 | Z8: =D12*100 -> 14.788585 | AA8: =Y8/Z8 -> 0.72804428 | AB8: =G12 -> 1029236.2 | AC8: =H12 -> 64887.765 | AD8: =AB8/AC8 -> 15.861792 | AE8: =I12 -> 1017761.7 | AF8: =J12 -> 24298.895 | AG8: =AE8/AF8 -> 41.885101
A9: % by Rev | B9: =B8/B7 -> 0.42882396 | O9: Atlassian | P9: TEAM | Q9: 53408 | R9: 73.8 | S9: 4.76 | V9: 5215 | W9: =V9+V9*(Z9/100) -> 6367.515 | X9: 19182.4 | Y9: =X9/V9 -> 3.6783126 | Z9: 22.1 | AA9: =Y9/Z9 -> 0.16643948 | AB9: 20394 | AC9: -68 | AE9: =Q9 -> 53408 | AF9: 1415 | AG9: =AE9/AF9 -> 37.74417
A10: % by Rev of CC from PB | B10: =B14/B8 -> 0.72648787 | E10: =E8*B10 -> 4.2493429 | F10: =F8*B10 -> 5.2649483 | G10: =G8*$B$10 -> 944964.89 | H10: =H8*$B$10 -> 59574.915 | I10: =I8*$B$10 -> 934429.88 | J10: =J8*$B$10 -> 22309.362 | K10: =K8*$B$10 -> 125.54877
A11: % by Rev of D from PB | B11: =B15/B8 -> 0.064787683 | E11: =E8*B11 -> 0.37895344 | F11: =F8*B11 -> 0.46952443 | G11: =G8*$B$11 -> 84271.311 | H11: =H8*$B$11 -> 5312.8495 | I11: =I8*$B$11 -> 83331.807 | J11: =J8*$B$11 -> 1989.5334 | K11: =K8*$B$11 -> 11.196352
A12: Total MSFT CCD | B12: =B14+B15 -> 95594 | C12: =C14+C15 -> 109731 | D12: =B16*D14+B17*D15 -> 0.14788585 | E12: =E10+E11 -> 4.6282963 | F12: =F10+F11 -> 5.7344727 | G12: =G10+G11 -> 1029236.2 | H12: =H10+H11 -> 64887.765 | I12: =I10+I11 -> 1017761.7 | J12: =J10+J11 -> 24298.895 | K12: =K10+K11 -> 136.74512
A14: Commercial prod & cloud | B14: 87767 | C14: 100815 | D14: =(C14-B14)/B14 -> 0.14866636 | O14: High | AA14: =AA8 -> 0.72804428 | AG14: =AG8 -> 41.885101
A15: Dynamics | B15: 7827 | C15: 8916 | D15: =(C15-B15)/B15 -> 0.13913377 | O15: Average | AA15: =AVERAGE(AA6:AA9) -> 0.44441525 | AG15: =AVERAGE(AG6:AG9) -> 29.51676
A16: Weight of CC | B16: =B14/B12 -> 0.91812248 | O16: Median | AA16: =MEDIAN(AA6:AA9) -> 0.44158863 | AD16: =AVERAGE(AD7:AD8) -> 15.036713 | AG16: =MEDIAN(AG6:AG9) -> 31.808711
A17: Weight of D | B17: =B15/B12 -> 0.081877524 | O17: Low | AA17: =AA9 -> 0.16643948 | AG17: =AG7 -> 12.564519
O21: ServiceNow | P21: =AA4 -> (EV/Rev)/RG% | Q21: =AG4 -> P/FCF
O22: Comparables Average | P22: =AA16 -> 0.44158863 | Q22: =AG16 -> 31.808711
O23: Implied EV/Rev Multiple | P23: =Z6*P22 -> 7.5070066
O24: Implied Enterprise Value | P24: =P23*W6 -> 116308.86
O25: Implied P/E Multiple
O26: NTM NI
O27: Net cash | P27: =BS!H11+BS!H13+BS!H20-BS!H35 -> 10106
O28: Implied Market Value | P28: =P24+P27 -> 126414.86 | Q28: =Q22*AF6 -> 145556.66
O29: Shares Outstanding | P29: 1046 | Q29: =P29 -> 1046
O30: Implied Value Per Share | P30: =P28/P29 -> 120.85551 | Q30: =Q28/Q29 -> 139.15551
O31: Weights | P31: 0.5 | Q31: 0.5
O32: Weighted Implied Share Price | P32: =P31*P30+Q31*Q30+T32*T30 -> 130.00551
O33: Current Price | P33: 121
O34: Change % | P34: =(P32-P33)/P33 -> 0.074425682
Q38: 0.33 | S38: =Q38*P32 -> 42.901817
Q39: 0.33 | S39: =Q38*DCF!G59 -> 58.361474
Q40: 0.33 | S40: =Q40*DCF!G79 -> 62.534552
S41: =SUM(S38:S40) -> 163.79784
A51: MSFT NTM EPS | B51: 16.9
A52: MSFT CY EPS | B52: 13.64
A53: MSFT EPS G% | B53: 0.24
A54: MSFT | J54: B&P ev
J55: =B56*B9 -> 1283598.7
A56: MSFT EV | B56: 2993300 | J56: =J55*#REF! -> #REF!
C57: cy eps | J57: =J55*B32 -> 0
A58: B&P NTM EPS | B58: =B51*B9 -> 7.2471248 | C58: =B52*B9 -> 5.8491588 | J58: =J56+J57 -> #REF!
A59: comm c | B59: =B58*#REF! -> #REF! | C59: =C58*#REF! -> #REF!
A60: dyn | B60: =B58*B32 -> 0 | C60: =C58*B32 -> 0
...

Sheet Summary
A1: =CoName -> ServiceNow | C1: Hist. | D1: Hist. | E1: Hist. | F1: Proj. | G1: Proj. | H1: Proj. | I1: Proj. | J1: Proj.
A2: Summary | C2: 2 | D2: =C2+1 -> 3 | E2: =D2+1 -> 4 | F2: =E2+1 -> 5 | G2: =F2+1 -> 6 | H2: =G2+1 -> 7 | I2: =H2+1 -> 8 | J2: =I2+1 -> 9
A4: Growth
A7: Profitability | K7: Valuation | Q7: WACC
K8: Method | L8: Implied Share Price | M8: Weight (%) | N8: Weight ($) | O8: Implied Share Price | Q8: Expected Market Return | R8: 0.108 | T8: Method | U8: % | V8: Fair Value Price | W8: Weighted Price
Q9: Risk Free Rate | R9: 0.0406 | T9: EV/EBITDA | U9: 0.33 | V9: =DCF!G59 -> 176.85295 | W9: =U9*V9 -> 58.361474
Q10: Market Risk Premium | R10: =R8-R9 -> 0.0674 | T10: EV/Rev | U10: 0.33 | V10: =DCF!G79 -> 189.49864 | W10: =U10*V10 -> 62.534552
Q11: Beta | R11: 1.26 | T11: Comps | U11: 0.34 | V11: =Comps!P32 -> 130.00551 | W11: =U11*V11 -> 44.201873
Q12: Cost of Equity | R12: =R11*R10+R9 -> 0.125524
A13: Asset turnover | Q13: Pre-Tax Cost of Debt | R13: 0.0406
Q14: Effective Tax Rate | R14: 0.21
Q15: After Tax Cost Of Debt | R15: =R13*(1-R14) -> 0.032074
Q16: Weight of Equity | R16: 0.985
A17: Credit | Q17: Weight of Debt | R17: 0.015
Q18: WACC | R18: =R16*R12+R17*R15 -> 0.12412225
T19: Implied Price | W19: =SUM(W9:W11) -> 165.0979
T20: Current Price | W20: 121
A21: x | B21: End | T21: Upside % | W21: =(W19-W20)/W20 -> 0.36444544

Sheet Charts 
A1: North America | B1: EMEA | C1: APAC | J1: Year | K1: 2025 | L1: 2026E | M1: 2027E | P1: Subscription | Q1: Other | T1: 2025 | U1: 2026E | V1: 2027E | BA1: 2022 | BB1: 2023 | BC1: 2024 | BD1: 2025
A2: 63 | B2: 25 | C2: 12 | J2: North America | K2: 8340 | L2: 10039.6 | M2: 11887 | P2: 97.03 | Q2: 2.97 | T2: 8800 | U2: 9200 | V2: 9500 | AB2: COmps MS | AO2: Comps | AY2: Magic Number | BA2: 0.82 | BB2: 0.78 | BC2: 0.88 | BD2: 0.85
J3: EMEA | K3: 3402 | L3: 4131.9 | M3: 4885.5 | U3: =(U2-T2)/T2 -> 0.045454545 | V3: =(V2-U2)/U2 -> 0.032608696 | AC3: NOW | AD3: TEAM | AE3: MSFT | AF3: Salesf | AG3: Others | AP3: ORCL | AQ3: SAP | AR3: MSFT | AS3: WDAY | AT3: Others
J4: APAC | K4: 1528 | L4: 1818.3 | M4: 2229.7 | AB4: IT Service Management | AC4: 44 | AD4: 15 | AG4: =100-(AC4+AD4) -> 41 | AI4: NOW = leader in large enterprise | AL4: TEAM = leader in mid markets | AO4: Enterprise Resource Management | AP4: 28 | AQ4: 24 | AR4: 18 | AS4: 6 | AT4: =100-(AP4+AQ4+AR4+AS4) -> 24 | BK4: 2022 | BL4: 2023 | BM4: 2024 | BN4: 2025
J5: Total | K5: =SUM(K2:K4) -> 13270 | L5: =SUM(L2:L4) -> 15989.8 | M5: =SUM(M2:M4) -> 19002.2 | AB5: CRM | AC5: 2 | AE5: 5.7 | AF5: 20.7 | AG5: =100-(AC5+AE5+AF5) -> 71.6 | BI5: Deferred Revenue % of crpo | BK5: =Assumptions!F26 -> 0.65449438 | BL5: =Assumptions!G26 -> 0.67899061 | BM5: =Assumptions!H26 -> 0.65004766 | BN5: =Assumptions!I26 -> 0.64700389
J6: North America | K6: =K2/K5 -> 0.62848531 | L6: =L2/L5 -> 0.62787527 | M6: =M2/M5 -> 0.62555915
J7: EMEA | K7: 0.25 | L7: =L3/L5 -> 0.25840849 | M7: =M3/M5 -> 0.25710181 | AB7: COmps MS | BA7: 2022 | BB7: 2023 | BC7: 2024 | BD7: 2025 | BK7: 2022 | BL7: 2023 | BM7: 2024 | BN7: 2025
J8: APAC | K8: =K4/K5 -> 0.11514695 | L8: =L4/L5 -> 0.11371624 | M8: =M4/M5 -> 0.11733904 | AD8: NOW | AE8: MSFT | AF8: CRM | AG8: Others | AY8: Rule of 50 (%) | BA8: 0.529 | BB8: 0.539 | BC8: 0.535 | BD8: 0.56 | BJ8: RPO % | BK8: =Assumptions!F21 -> 0.25217391 | BL8: =Assumptions!G21 -> 0.25 | BM8: =Assumptions!H21 -> 0.23888889 | BN8: =Assumptions!I21 -> 0.26457399
AB10: Client Relationship Management | AD10: 2 | AE10: 5.7 | AF10: 20.7 | AG10: =100-(AD10+AE10+AF10) -> 71.6
BA14: 2022 | BB14: 2023 | BC14: 2024 | BD14: 2025
AY15: Crpo/Rpo Ratio | BA15: =Assumptions!F23 -> 0.49444444 | BB15: =Assumptions!G23 -> 0.47333333 | BC15: =Assumptions!H23 -> 0.47040359 | BD15: =Assumptions!I23 -> 0.45567376
BA19: 2022 | BB19: 2023 | BC19: 2024 | BD19: 2025
AY20: FCF | BA20: =CFS!E11+CFS!E14 -> 2173 | BB20: =CFS!F11+CFS!F14 -> 2704 | BC20: =CFS!G11+CFS!G14 -> 3415 | BD20: =CFS!H11+CFS!H14 -> 4576
AY21: %change | BB21: =(BB20-BA20)/BA20 -> 0.24436263 | BC21: =(BC20-BB20)/BB20 -> 0.26294379 | BD21: =(BD20-BC20)/BC20 -> 0.33997072
AY26: ServiceNow Tier | AZ26: Estimated Price (per user/month) | BA26: Key Features & 2026 Context
O27: 2021 | P27: 2022 | Q27: 2023 | R27: 2024 | S27: 2025 | T27: 2026E | U27: 2027E | AY27: ITSM Standard | AZ27: $70 - $100
O28: 7.4 | P28: 7.7 | Q28: 8.1 | R28: 8.4 | S28: 8.8 | T28: 9.2 | U28: 9.5 | AY28: ITSM Professional | AZ28: $120 - $150
P29: =(P28-O28)/O28 -> 0.040540541 | Q29: =(Q28-P28)/P28 -> 0.051948052 | R29: =(R28-Q28)/Q28 -> 0.037037037 | S29: =(S28-R28)/R28 -> 0.047619048 | T29: =(T28-S28)/S28 -> 0.045454545 | U29: =(U28-T28)/T28 -> 0.032608696 | AY29: ITSM Enterprise | AZ29: $160 - $200+
AY30: Pro Plus (AI SKU) | AZ30: +50% to 60% Uplift
AH33: NNACV Across Solution Segments
AJ34: 2021 | AK34: 2022 | AL34: 2023 | AM34: 2024 | AN34: 2025
AH35: Technology | AJ35: 57 | AK35: 59 | AL35: 55 | AM35: 52 | AN35: 47
AH36: CRM & Core | AJ36: 28 | AK36: 26 | AL36: 29 | AM36: 30 | AN36: 31
AH37: Creator | AJ37: 15 | AK37: 15 | AL37: 16 | AM37: 18 | AN37: 22
AV38: 2024 | AW38: 2025 | AX38: 2026
AT39: NNACV in Now Assist (in millions) | AV39: 250 | AW39: 600 | AX39: 1000
C41: For FY2025
C42: Subs rev | D42: 12883000000 | H42: 2020 | I42: 2021 | J42: 2022 | K42: 2023 | L42: 2024 | M42: 2025 | N42: 2026E | O42: 2027E
C43: no of cust | D43: 8800 | G43: Top Line rev | H43: =4519/1000 -> 4.519 | I43: 5.89 | J43: 7.25 | K43: 8.97 | L43: 10.98 | M43: 13.28 | N43: 15.99 | O43: 18.95
C44: no of cust ACV > $5M | D44: 603 | G44: Rev growth | I44: =(I43-H43)/H43 -> 0.3033857 | J44: =(J43-I43)/I43 -> 0.23089983 | K44: =(K43-J43)/J43 -> 0.23724138 | L44: =(L43-K43)/K43 -> 0.22408027 | M44: =(M43-L43)/L43 -> 0.20947177 | N44: =(N43-M43)/M43 -> 0.20406627 | O44: =(O43-N43)/N43 -> 0.1851157
C45: avg ACV | D45: 14700000
C46: no of prem cust % | D46: =D44/D43 -> 0.068522727
C47: no of prem cust rev % | D47: =D44*D45 -> 8864100000
C48: prem cust rev % of total rev | D48: =D47/D42 -> 0.68804626
